[2020-07-12 23:24:47] ERROR 19108:[base.py:706] - Exception during reset or similar
Traceback (most recent call last):
  File "G:\technology\ezio-framework\backend_flask\venv\lib\site-packages\pymysql\connections.py", line 691, in _read_bytes
    data = self._rfile.read(num_bytes)
  File "C:\python3.6\lib\socket.py", line 586, in readinto
    return self._sock.recv_into(b)
TimeoutError: [WinError 10060] 由于连接方在一段时间后没有正确答复或连接的主机没有反应，连接尝试失败。

During handling of the above exception, another exception occurred:

Traceback (most recent call last):
  File "G:\technology\ezio-framework\backend_flask\venv\lib\site-packages\sqlalchemy\engine\base.py", line 752, in _rollback_impl
    self.engine.dialect.do_rollback(self.connection)
  File "G:\technology\ezio-framework\backend_flask\venv\lib\site-packages\sqlalchemy\dialects\mysql\base.py", line 2351, in do_rollback
    dbapi_connection.rollback()
  File "G:\technology\ezio-framework\backend_flask\venv\lib\site-packages\pymysql\connections.py", line 430, in rollback
    self._read_ok_packet()
  File "G:\technology\ezio-framework\backend_flask\venv\lib\site-packages\pymysql\connections.py", line 394, in _read_ok_packet
    pkt = self._read_packet()
  File "G:\technology\ezio-framework\backend_flask\venv\lib\site-packages\pymysql\connections.py", line 657, in _read_packet
    packet_header = self._read_bytes(4)
  File "G:\technology\ezio-framework\backend_flask\venv\lib\site-packages\pymysql\connections.py", line 699, in _read_bytes
    "Lost connection to MySQL server during query (%s)" % (e,))
pymysql.err.OperationalError: (2013, 'Lost connection to MySQL server during query ([WinError 10060] 由于连接方在一段时间后没有正确答复或连接的主机没有反应，连接尝试失败。)')

The above exception was the direct cause of the following exception:

Traceback (most recent call last):
  File "G:\technology\ezio-framework\backend_flask\venv\lib\site-packages\sqlalchemy\pool\base.py", line 697, in _finalize_fairy
    fairy._reset(pool)
  File "G:\technology\ezio-framework\backend_flask\venv\lib\site-packages\sqlalchemy\pool\base.py", line 891, in _reset
    self._reset_agent.rollback()
  File "G:\technology\ezio-framework\backend_flask\venv\lib\site-packages\sqlalchemy\engine\base.py", line 1760, in rollback
    self._do_rollback()
  File "G:\technology\ezio-framework\backend_flask\venv\lib\site-packages\sqlalchemy\engine\base.py", line 1798, in _do_rollback
    self.connection._rollback_impl()
  File "G:\technology\ezio-framework\backend_flask\venv\lib\site-packages\sqlalchemy\engine\base.py", line 754, in _rollback_impl
    self._handle_dbapi_exception(e, None, None, None, None)
  File "G:\technology\ezio-framework\backend_flask\venv\lib\site-packages\sqlalchemy\engine\base.py", line 1518, in _handle_dbapi_exception
    sqlalchemy_exception, with_traceback=exc_info[2], from_=e
  File "G:\technology\ezio-framework\backend_flask\venv\lib\site-packages\sqlalchemy\util\compat.py", line 178, in raise_
    raise exception
  File "G:\technology\ezio-framework\backend_flask\venv\lib\site-packages\sqlalchemy\engine\base.py", line 752, in _rollback_impl
    self.engine.dialect.do_rollback(self.connection)
  File "G:\technology\ezio-framework\backend_flask\venv\lib\site-packages\sqlalchemy\dialects\mysql\base.py", line 2351, in do_rollback
    dbapi_connection.rollback()
  File "G:\technology\ezio-framework\backend_flask\venv\lib\site-packages\pymysql\connections.py", line 430, in rollback
    self._read_ok_packet()
  File "G:\technology\ezio-framework\backend_flask\venv\lib\site-packages\pymysql\connections.py", line 394, in _read_ok_packet
    pkt = self._read_packet()
  File "G:\technology\ezio-framework\backend_flask\venv\lib\site-packages\pymysql\connections.py", line 657, in _read_packet
    packet_header = self._read_bytes(4)
  File "G:\technology\ezio-framework\backend_flask\venv\lib\site-packages\pymysql\connections.py", line 699, in _read_bytes
    "Lost connection to MySQL server during query (%s)" % (e,))
sqlalchemy.exc.OperationalError: (pymysql.err.OperationalError) (2013, 'Lost connection to MySQL server during query ([WinError 10060] 由于连接方在一段时间后没有正确答复或连接的主机没有反应，连接尝试失败。)')
(Background on this error at: http://sqlalche.me/e/e3q8)
[2020-07-13 17:18:20] ERROR 15624:[base.py:706] - Exception during reset or similar
Traceback (most recent call last):
  File "G:\technology\ezio-framework\backend_flask\venv\lib\site-packages\pymysql\connections.py", line 691, in _read_bytes
    data = self._rfile.read(num_bytes)
  File "C:\python3.6\lib\socket.py", line 586, in readinto
    return self._sock.recv_into(b)
TimeoutError: [WinError 10060] 由于连接方在一段时间后没有正确答复或连接的主机没有反应，连接尝试失败。

During handling of the above exception, another exception occurred:

Traceback (most recent call last):
  File "G:\technology\ezio-framework\backend_flask\venv\lib\site-packages\sqlalchemy\engine\base.py", line 752, in _rollback_impl
    self.engine.dialect.do_rollback(self.connection)
  File "G:\technology\ezio-framework\backend_flask\venv\lib\site-packages\sqlalchemy\dialects\mysql\base.py", line 2351, in do_rollback
    dbapi_connection.rollback()
  File "G:\technology\ezio-framework\backend_flask\venv\lib\site-packages\pymysql\connections.py", line 430, in rollback
    self._read_ok_packet()
  File "G:\technology\ezio-framework\backend_flask\venv\lib\site-packages\pymysql\connections.py", line 394, in _read_ok_packet
    pkt = self._read_packet()
  File "G:\technology\ezio-framework\backend_flask\venv\lib\site-packages\pymysql\connections.py", line 657, in _read_packet
    packet_header = self._read_bytes(4)
  File "G:\technology\ezio-framework\backend_flask\venv\lib\site-packages\pymysql\connections.py", line 699, in _read_bytes
    "Lost connection to MySQL server during query (%s)" % (e,))
pymysql.err.OperationalError: (2013, 'Lost connection to MySQL server during query ([WinError 10060] 由于连接方在一段时间后没有正确答复或连接的主机没有反应，连接尝试失败。)')

The above exception was the direct cause of the following exception:

Traceback (most recent call last):
  File "G:\technology\ezio-framework\backend_flask\venv\lib\site-packages\sqlalchemy\pool\base.py", line 697, in _finalize_fairy
    fairy._reset(pool)
  File "G:\technology\ezio-framework\backend_flask\venv\lib\site-packages\sqlalchemy\pool\base.py", line 891, in _reset
    self._reset_agent.rollback()
  File "G:\technology\ezio-framework\backend_flask\venv\lib\site-packages\sqlalchemy\engine\base.py", line 1760, in rollback
    self._do_rollback()
  File "G:\technology\ezio-framework\backend_flask\venv\lib\site-packages\sqlalchemy\engine\base.py", line 1798, in _do_rollback
    self.connection._rollback_impl()
  File "G:\technology\ezio-framework\backend_flask\venv\lib\site-packages\sqlalchemy\engine\base.py", line 754, in _rollback_impl
    self._handle_dbapi_exception(e, None, None, None, None)
  File "G:\technology\ezio-framework\backend_flask\venv\lib\site-packages\sqlalchemy\engine\base.py", line 1518, in _handle_dbapi_exception
    sqlalchemy_exception, with_traceback=exc_info[2], from_=e
  File "G:\technology\ezio-framework\backend_flask\venv\lib\site-packages\sqlalchemy\util\compat.py", line 178, in raise_
    raise exception
  File "G:\technology\ezio-framework\backend_flask\venv\lib\site-packages\sqlalchemy\engine\base.py", line 752, in _rollback_impl
    self.engine.dialect.do_rollback(self.connection)
  File "G:\technology\ezio-framework\backend_flask\venv\lib\site-packages\sqlalchemy\dialects\mysql\base.py", line 2351, in do_rollback
    dbapi_connection.rollback()
  File "G:\technology\ezio-framework\backend_flask\venv\lib\site-packages\pymysql\connections.py", line 430, in rollback
    self._read_ok_packet()
  File "G:\technology\ezio-framework\backend_flask\venv\lib\site-packages\pymysql\connections.py", line 394, in _read_ok_packet
    pkt = self._read_packet()
  File "G:\technology\ezio-framework\backend_flask\venv\lib\site-packages\pymysql\connections.py", line 657, in _read_packet
    packet_header = self._read_bytes(4)
  File "G:\technology\ezio-framework\backend_flask\venv\lib\site-packages\pymysql\connections.py", line 699, in _read_bytes
    "Lost connection to MySQL server during query (%s)" % (e,))
sqlalchemy.exc.OperationalError: (pymysql.err.OperationalError) (2013, 'Lost connection to MySQL server during query ([WinError 10060] 由于连接方在一段时间后没有正确答复或连接的主机没有反应，连接尝试失败。)')
(Background on this error at: http://sqlalche.me/e/e3q8)
